2025-06-01 00:11:10,957 INFO    MainThread:1137672 [wandb_setup.py:_flush():70] Current SDK version is 0.19.11
2025-06-01 00:11:10,957 INFO    MainThread:1137672 [wandb_setup.py:_flush():70] Configure stats pid to 1137672
2025-06-01 00:11:10,957 INFO    MainThread:1137672 [wandb_setup.py:_flush():70] Loading settings from /home/hector/.config/wandb/settings
2025-06-01 00:11:10,957 INFO    MainThread:1137672 [wandb_setup.py:_flush():70] Loading settings from /home/hector/Ads/wandb/settings
2025-06-01 00:11:10,957 INFO    MainThread:1137672 [wandb_setup.py:_flush():70] Loading settings from environment variables
2025-06-01 00:11:10,957 INFO    MainThread:1137672 [wandb_init.py:setup_run_log_directory():724] Logging user logs to /home/hector/Ads/wandb/run-20250601_001110-vyw4sh6v/logs/debug.log
2025-06-01 00:11:10,958 INFO    MainThread:1137672 [wandb_init.py:setup_run_log_directory():725] Logging internal logs to /home/hector/Ads/wandb/run-20250601_001110-vyw4sh6v/logs/debug-internal.log
2025-06-01 00:11:10,958 INFO    MainThread:1137672 [wandb_init.py:init():852] calling init triggers
2025-06-01 00:11:10,958 INFO    MainThread:1137672 [wandb_init.py:init():857] wandb.init called with sweep_config: {}
config: {'_wandb': {}}
2025-06-01 00:11:10,958 INFO    MainThread:1137672 [wandb_init.py:init():893] starting backend
2025-06-01 00:11:10,958 INFO    MainThread:1137672 [wandb_init.py:init():897] sending inform_init request
2025-06-01 00:11:10,961 INFO    MainThread:1137672 [backend.py:_multiprocessing_setup():101] multiprocessing start_methods=fork,spawn,forkserver, using: spawn
2025-06-01 00:11:10,962 INFO    MainThread:1137672 [wandb_init.py:init():907] backend started and connected
2025-06-01 00:11:10,965 INFO    MainThread:1137672 [wandb_init.py:init():1005] updated telemetry
2025-06-01 00:11:10,973 INFO    MainThread:1137672 [wandb_init.py:init():1029] communicating run to backend with 90.0 second timeout
2025-06-01 00:11:42,163 INFO    Thread-4 (wrapped_target):1137672 [retry.py:__call__():175] [no run ID] Retry attempt failed:
Traceback (most recent call last):
  File "/home/hector/miniconda3/envs/dpo-training/lib/python3.10/site-packages/urllib3/connection.py", line 198, in _new_conn
    sock = connection.create_connection(
  File "/home/hector/miniconda3/envs/dpo-training/lib/python3.10/site-packages/urllib3/util/connection.py", line 85, in create_connection
    raise err
  File "/home/hector/miniconda3/envs/dpo-training/lib/python3.10/site-packages/urllib3/util/connection.py", line 73, in create_connection
    sock.connect(sa)
TimeoutError: timed out

The above exception was the direct cause of the following exception:

Traceback (most recent call last):
  File "/home/hector/miniconda3/envs/dpo-training/lib/python3.10/site-packages/urllib3/connectionpool.py", line 787, in urlopen
    response = self._make_request(
  File "/home/hector/miniconda3/envs/dpo-training/lib/python3.10/site-packages/urllib3/connectionpool.py", line 488, in _make_request
    raise new_e
  File "/home/hector/miniconda3/envs/dpo-training/lib/python3.10/site-packages/urllib3/connectionpool.py", line 464, in _make_request
    self._validate_conn(conn)
  File "/home/hector/miniconda3/envs/dpo-training/lib/python3.10/site-packages/urllib3/connectionpool.py", line 1093, in _validate_conn
    conn.connect()
  File "/home/hector/miniconda3/envs/dpo-training/lib/python3.10/site-packages/urllib3/connection.py", line 704, in connect
    self.sock = sock = self._new_conn()
  File "/home/hector/miniconda3/envs/dpo-training/lib/python3.10/site-packages/urllib3/connection.py", line 207, in _new_conn
    raise ConnectTimeoutError(
urllib3.exceptions.ConnectTimeoutError: (<urllib3.connection.HTTPSConnection object at 0x7f36c1f2a290>, 'Connection to api.wandb.ai timed out. (connect timeout=20)')

The above exception was the direct cause of the following exception:

Traceback (most recent call last):
  File "/home/hector/miniconda3/envs/dpo-training/lib/python3.10/site-packages/requests/adapters.py", line 667, in send
    resp = conn.urlopen(
  File "/home/hector/miniconda3/envs/dpo-training/lib/python3.10/site-packages/urllib3/connectionpool.py", line 841, in urlopen
    retries = retries.increment(
  File "/home/hector/miniconda3/envs/dpo-training/lib/python3.10/site-packages/urllib3/util/retry.py", line 519, in increment
    raise MaxRetryError(_pool, url, reason) from reason  # type: ignore[arg-type]
urllib3.exceptions.MaxRetryError: HTTPSConnectionPool(host='api.wandb.ai', port=443): Max retries exceeded with url: /graphql (Caused by ConnectTimeoutError(<urllib3.connection.HTTPSConnection object at 0x7f36c1f2a290>, 'Connection to api.wandb.ai timed out. (connect timeout=20)'))

During handling of the above exception, another exception occurred:

Traceback (most recent call last):
  File "/home/hector/miniconda3/envs/dpo-training/lib/python3.10/site-packages/wandb/sdk/lib/retry.py", line 134, in __call__
    result = self._call_fn(*args, **kwargs)
  File "/home/hector/miniconda3/envs/dpo-training/lib/python3.10/site-packages/wandb/sdk/internal/internal_api.py", line 398, in execute
    return self.client.execute(*args, **kwargs)  # type: ignore
  File "/home/hector/miniconda3/envs/dpo-training/lib/python3.10/site-packages/wandb/vendor/gql-0.2.0/wandb_gql/client.py", line 52, in execute
    result = self._get_result(document, *args, **kwargs)
  File "/home/hector/miniconda3/envs/dpo-training/lib/python3.10/site-packages/wandb/vendor/gql-0.2.0/wandb_gql/client.py", line 60, in _get_result
    return self.transport.execute(document, *args, **kwargs)
  File "/home/hector/miniconda3/envs/dpo-training/lib/python3.10/site-packages/wandb/sdk/lib/gql_request.py", line 58, in execute
    request = self.session.post(self.url, **post_args)
  File "/home/hector/miniconda3/envs/dpo-training/lib/python3.10/site-packages/requests/sessions.py", line 637, in post
    return self.request("POST", url, data=data, json=json, **kwargs)
  File "/home/hector/miniconda3/envs/dpo-training/lib/python3.10/site-packages/requests/sessions.py", line 589, in request
    resp = self.send(prep, **send_kwargs)
  File "/home/hector/miniconda3/envs/dpo-training/lib/python3.10/site-packages/requests/sessions.py", line 703, in send
    r = adapter.send(request, **kwargs)
  File "/home/hector/miniconda3/envs/dpo-training/lib/python3.10/site-packages/requests/adapters.py", line 688, in send
    raise ConnectTimeout(e, request=request)
requests.exceptions.ConnectTimeout: HTTPSConnectionPool(host='api.wandb.ai', port=443): Max retries exceeded with url: /graphql (Caused by ConnectTimeoutError(<urllib3.connection.HTTPSConnection object at 0x7f36c1f2a290>, 'Connection to api.wandb.ai timed out. (connect timeout=20)'))
2025-06-01 00:11:59,856 WARNING MainThread:1137672 [wandb_init.py:init():1681] [no run ID] interrupted
Traceback (most recent call last):
  File "/home/hector/miniconda3/envs/dpo-training/lib/python3.10/site-packages/wandb/sdk/wandb_init.py", line 1677, in init
    return wi.init(run_settings, run_config, run_printer)
  File "/home/hector/miniconda3/envs/dpo-training/lib/python3.10/site-packages/wandb/sdk/wandb_init.py", line 1055, in init
    result = wait_with_progress(
  File "/home/hector/miniconda3/envs/dpo-training/lib/python3.10/site-packages/wandb/sdk/mailbox/wait_with_progress.py", line 24, in wait_with_progress
    return wait_all_with_progress(
  File "/home/hector/miniconda3/envs/dpo-training/lib/python3.10/site-packages/wandb/sdk/mailbox/wait_with_progress.py", line 87, in wait_all_with_progress
    return asyncio_compat.run(progress_loop_with_timeout)
  File "/home/hector/miniconda3/envs/dpo-training/lib/python3.10/site-packages/wandb/sdk/lib/asyncio_compat.py", line 30, in run
    return future.result()
  File "/home/hector/miniconda3/envs/dpo-training/lib/python3.10/concurrent/futures/_base.py", line 453, in result
    self._condition.wait(timeout)
  File "/home/hector/miniconda3/envs/dpo-training/lib/python3.10/threading.py", line 320, in wait
    waiter.acquire()
KeyboardInterrupt
2025-06-01 00:12:00,010 INFO    MsgRouterThr:1137672 [mailbox.py:close():129] [no run ID] Closing mailbox, abandoning 2 handles.
